Workbook

Sheet Mapa Financiero
B1: @rs.finanzas.seguros
B2: 📊 TU MAPA FINANCIERO — PASO 1: ORDEN Y CLARIDAD
B3: Mes / Período:
B5: Instrucciones: • Completá únicamente las celdas amarillas con los montos de tu mes. • Sé realista: diferenciá bien tus Gastos Innegociables (los que sostienen tu estructura) de los Variables y Disfrute. • Los totales y el Fondo de Oxígeno se calculan solos, no toques esas celdas.
B10: 1. INGRESOS MENSUALES
B11: Concepto | C11: Monto Mensual
B12: Honorarios / Facturación Base | C12: 850000
B13: Ingresos Extra / Variables | C13: 0
B14: Rentas / Otros | C14: 0
B15: TOTAL INGRESOS | C15: =SUM(C12:C14) -> $ 850,000
B17: 2. GASTOS INNEGOCIABLES (Tu Estructura Vital)
B18: Concepto | C18: Monto Mensual
B19: Vivienda (Alquiler / Expensas / Hipoteca) | C19: 300000
B20: Servicios (Luz, Gas, Internet, Agua) | C20: 0
B21: Salud (Prepaga / Farmacia) | C21: 0
B22: Educación (Colegios / Facultad) | C22: 0
B23: Supermercado (Alimentación Básica) | C23: 0
B24: Seguros (Auto / Hogar) | C24: 0
B25: Impuestos (Monotributo / IIBB) | C25: 0
B26: TOTAL INNEGOCIABLES | C26: =SUM(C19:C25) -> $ 300,000
B28: 3. VARIABLES Y DISFRUTE (Crecimiento y Ocio)
B29: Concepto | C29: Monto Mensual
B30: Salidas y Comidas Afuera | C30: 0
B31: Suscripciones (Netflix, Spotify, Apps) | C31: 0
B32: Cuidado Personal / Estética | C32: 0
B33: Transporte (Nafta / Movilidad / Taxis) | C33: 0
B34: Regalos / Extras | C34: 0
B35: Gimnasio / Deportes / Hobbies | C35: 0
B36: TOTAL VARIABLES | C36: =SUM(C30:C35) -> -
B38: 4. RESUMEN DE TU MES (La Foto Completa)
B39: Concepto | C39: Monto Mensual
B40: Ingresos Totales | C40: =C15 -> $ 850,000
B41: (–) Gastos Innegociables | C41: =-C26 -> -$ 300,000
B42: (–) Gastos Variables y Disfrute | C42: =-C36 -> -
B43: FLUJO LIBRE (Para Invertir / Ahorrar) | C43: =C15-C26-C36 -> $ 550,000
B45: 5. TU FONDO DE OXÍGENO (El Respaldo para tu Tranquilidad)
B46: Concepto | C46: Cálculo / Resultado
B47: Total Gastos Innegociables Mensuales | C47: =C26 -> $ 300,000
B48: Nivel 1: Transición (3 meses de oxígeno) | C48: =C47*3 -> $ 900,000
B49: Nivel 2: Tranquilidad Total (6 meses de oxígeno) | C49: =C47*6 -> $ 1,800,000
...

Sheet Gráfico
B2: 📈 VISUALIZÁ TU MES
B4: Distribución de tu Ingreso
B5: Categoría | C5: Monto
B6: Gastos Innegociables | C6: ='Mapa Financiero'!C26 -> $ 300,000
B7: Gastos Variables y Disfrute | C7: ='Mapa Financiero'!C36 -> -
B8: Flujo Libre (Ahorro/Inversión) | C8: ='Mapa Financiero'!C43 -> $ 550,000
B11: Detalle de Gastos (Innegociables + Variables)
B12: Concepto | C12: Monto
B13: Vivienda (Alquiler / Expensas / Hipoteca) | C13: ='Mapa Financiero'!C19 -> $ 300,000
B14: Servicios (Luz, Gas, Internet, Agua) | C14: ='Mapa Financiero'!C20 -> -
B15: Salud (Prepaga / Farmacia) | C15: ='Mapa Financiero'!C21 -> -
B16: Educación (Colegios / Facultad) | C16: ='Mapa Financiero'!C22 -> -
B17: Supermercado (Alimentación Básica) | C17: ='Mapa Financiero'!C23 -> -
B18: Seguros (Auto / Hogar) | C18: ='Mapa Financiero'!C24 -> -
B19: Impuestos (Monotributo / IIBB) | C19: ='Mapa Financiero'!C25 -> -
B20: Salidas y Comidas Afuera | C20: ='Mapa Financiero'!C30 -> -
B21: Suscripciones (Netflix, Spotify, Apps) | C21: ='Mapa Financiero'!C31 -> -
B22: Cuidado Personal / Estética | C22: ='Mapa Financiero'!C32 -> -
B23: Transporte (Nafta / Movilidad / Taxis) | C23: ='Mapa Financiero'!C33 -> -
B24: Regalos / Extras | C24: ='Mapa Financiero'!C34 -> -
B25: Gimnasio / Deportes / Hobbies | C25: ='Mapa Financiero'!C35 -> -

Sheet Deudas y Meta de Pago
B2: 💳 DEUDAS: VISIBILIDAD Y META DE PAGO
B3: Instrucciones: • Cargá cada deuda (tarjetas primero, son las de mayor interés). Completá saldo, tasa y pago mínimo. • En 'Meta de Pago Mensual' definí cuánto vas a destinar cada mes a esa deuda (tiene que ser ≥ al pago mínimo). • La columna Prioridad ordena automáticamente qué deuda atacar primero (mayor tasa de interés = mayor urgencia). • Dejá saldo en $0 en las filas que no uses.
B8: TUS DEUDAS ACTUALES
B9: Deuda | C9: Tipo | D9: Saldo Actual | E9: Tasa Interés Anual (%) | F9: Pago Mínimo Mensual | G9: Meta de Pago Mensual | H9: Prioridad | I9: Meses Estimados
B10: Tarjeta de Crédito 1 | C10: Tarjeta | D10: 250000 | E10: 140 | F10: 12500 | G10: 20000 | H10: =IF(D10=0,"-",RANK(E10,$E$10:$E$16,0)) -> 1 | I10: =IF(G10=0,"-",ROUNDUP(D10/G10,0)) -> 13
B11: Tarjeta de Crédito 2 | C11: Tarjeta | D11: 0 | E11: 140 | F11: 0 | G11: 0 | H11: =IF(D11=0,"-",RANK(E11,$E$10:$E$16,0)) -> - | I11: =IF(G11=0,"-",ROUNDUP(D11/G11,0)) -> -
B12: Tarjeta de Crédito 3 | C12: Tarjeta | D12: 0 | E12: 140 | F12: 0 | G12: 0 | H12: =IF(D12=0,"-",RANK(E12,$E$10:$E$16,0)) -> - | I12: =IF(G12=0,"-",ROUNDUP(D12/G12,0)) -> -
B13: Préstamo Personal | C13: Préstamo | D13: 0 | E13: 80 | F13: 0 | G13: 0 | H13: =IF(D13=0,"-",RANK(E13,$E$10:$E$16,0)) -> - | I13: =IF(G13=0,"-",ROUNDUP(D13/G13,0)) -> -
B14: Crédito Prendario / Auto | C14: Crédito | D14: 0 | E14: 60 | F14: 0 | G14: 0 | H14: =IF(D14=0,"-",RANK(E14,$E$10:$E$16,0)) -> - | I14: =IF(G14=0,"-",ROUNDUP(D14/G14,0)) -> -
B15: Otro 1 | C15: Otro | D15: 0 | E15: 0 | F15: 0 | G15: 0 | H15: =IF(D15=0,"-",RANK(E15,$E$10:$E$16,0)) -> - | I15: =IF(G15=0,"-",ROUNDUP(D15/G15,0)) -> -
B16: Otro 2 | C16: Otro | D16: 0 | E16: 0 | F16: 0 | G16: 0 | H16: =IF(D16=0,"-",RANK(E16,$E$10:$E$16,0)) -> - | I16: =IF(G16=0,"-",ROUNDUP(D16/G16,0)) -> -
B17: TOTAL DEUDAS | D17: =SUM(D10:D16) -> $ 250,000 | F17: =SUM(F10:F16) -> $ 12,500 | G17: =SUM(G10:G16) -> $ 20,000
B20: META GENERAL: LIBRE DE DEUDAS
B21: Deuda Total Actual | G21: =D17 -> $ 250,000
B22: Tu Flujo Libre Mensual (Hoja 1 - Mapa Financiero) | G22: ='Mapa Financiero'!C43 -> $ 550,000
B23: Meta de Pago Mensual Total (esta hoja) | G23: =G17 -> $ 20,000
B24: ¿Tu meta de pago está cubierta por tu Flujo Libre? | G24: =IF(G22>=G23,"✅ Sí, alcanza","⚠️ No alcanza, revisá gastos variables") -> ✅ Sí, alcanza
B25: Meses Estimados para quedar Libre de Deudas | G25: =IF(G23=0,"-",ROUNDUP(D17/G23,0)) -> 13 meses
B26: Fecha Estimada de 'Deuda Cero' | G26: =IF(G25="-","-",EDATE(TODAY(),G25)) -> September 2027
B28: 💡 Tip: priorizá siempre la deuda con Prioridad 1 (mayor tasa de interés) — ahí es donde más plata perdés cada mes.
